#VRML_SIM R2020a utf8
WorldInfo {
}
Viewpoint {
  orientation -0.0088723824790286 -0.9774227779000316 -0.21110659409722723 3.0883156486160943
  position 0.05102291814383114 1.0590387164724027 -2.228526423590723
}
TexturedBackground {
}
TexturedBackgroundLight {
}
RectangleArena {
  floorSize 2 2
  wallHeight 0.15
}
DEF Slave Robot {
  translation 0.08998262249482811 0.03972097929869594 -0.14965536827151762
  rotation 1.6780519576067358e-08 0.9999999999999997 1.771087714796681e-08 1.5169451928295523
  children [
    DEF receiver Receiver {
      type "infra-red"
      channel 2
    }
    DEF emitter Emitter {
      type "serial"
      channel 1
      byteSize 128
    }
    GPS {
      children [
        Solid {
          translation 0 0.03 0.07
          children [
            Shape {
              appearance PBRAppearance {
                baseColor 1 1 0.0980392
                roughness 1
                metalness 0
              }
              geometry Cone {
                bottomRadius 0.03
                height 0.06
              }
            }
          ]
        }
      ]
      name "global"
    }
    DEF BODY Shape {
      appearance PBRAppearance {
        baseColor 0.917647 0.145098 0.145098
        roughness 1
        metalness 0
      }
      geometry Box {
        size 0.1 0.05 0.2
      }
    }
    DEF WHEEL1 HingeJoint {
      jointParameters HingeJointParameters {
        position 1195.9019042226655
        anchor 0.06 0 0.05
      }
      device [
        RotationalMotor {
          name "wheel1"
        }
      ]
      endPoint Solid {
        translation 0.06 0 0.05
        rotation 0.6549004017474791 -0.6549028073356377 0.3771044639551369 2.42036627495726
        children [
          DEF WHEEL Shape {
            appearance PBRAppearance {
              baseColor 0.305882 0.898039 0.25098
              roughness 1
              metalness 0
            }
            geometry Cylinder {
              height 0.02
              radius 0.04
              subdivision 24
            }
          }
        ]
        boundingObject USE WHEEL
        physics Physics {
        }
      }
    }
    DEF WHEEL2 HingeJoint {
      jointParameters HingeJointParameters {
        position 909.2499632604132
        anchor -0.06 0 0.05
      }
      device [
        RotationalMotor {
          name "wheel2"
        }
      ]
      endPoint Solid {
        translation -0.06 0 0.05
        rotation 0.6184512194444661 -0.6184534911467954 -0.48480240145444126 4.044421327312176
        children [
          USE WHEEL
        ]
        name "solid(1)"
        boundingObject USE WHEEL
        physics Physics {
        }
      }
    }
    DEF WHEEL3 HingeJoint {
      jointParameters HingeJointParameters {
        position 1195.90196805295
        anchor 0.06 0 -0.05
      }
      device [
        RotationalMotor {
          name "wheel3"
        }
      ]
      endPoint Solid {
        translation 0.06 0 -0.05
        rotation 0.65490727490041 -0.6549096805138184 0.37708059039389324 2.420408077655574
        children [
          USE WHEEL
        ]
        name "solid(2)"
        boundingObject USE WHEEL
        physics Physics {
        }
      }
    }
    DEF WHEEL4 HingeJoint {
      jointParameters HingeJointParameters {
        position 909.2500359983497
        anchor -0.06 0 -0.05
      }
      device [
        RotationalMotor {
          name "wheel4"
        }
      ]
      endPoint Solid {
        translation -0.06 0 -0.05
        rotation 0.6184403311211003 -0.6184426027834337 -0.4848301804810381 4.044466311781727
        children [
          USE WHEEL
        ]
        name "solid(3)"
        boundingObject USE WHEEL
        physics Physics {
        }
      }
    }
    DEF DS_RIGHT DistanceSensor {
      translation -0.03 0 0.1
      rotation 0 1 0 -1.87079
      children [
        Shape {
          appearance PBRAppearance {
            baseColor 0.184314 0.596078 0.847059
            roughness 1
            metalness 0
          }
          geometry Box {
            size 0.01 0.01 0.01
          }
        }
      ]
      name "ds_right"
    }
    DEF DS_LEFT DistanceSensor {
      translation 0.03 0 0.1
      rotation 0 1 0 -1.27079
      children [
        Shape {
          appearance PBRAppearance {
            baseColor 0.184314 0.596078 0.847059
            roughness 1
            metalness 0
          }
          geometry Box {
            size 0.01 0.01 0.01
          }
        }
      ]
      name "ds_left"
    }
  ]
  boundingObject USE BODY
  physics Physics {
    density -1
    mass 1
  }
  controller "communication"
  supervisor TRUE
}
DEF Central Robot {
  translation 0.8947100002149113 0.039721021687696714 0.8503569999802452
  rotation -4.517300650960767e-08 0.9999999999999989 2.061713019520603e-09 -3.0503753071789785
  children [
    DEF receiver Receiver {
      type "serial"
      channel -1
      byteSize 128
    }
    GPS {
      children [
        Solid {
          translation 0 0.03 0.07
          children [
            Shape {
              appearance PBRAppearance {
                baseColor 1 1 0.0980392
                roughness 1
                metalness 0
              }
              geometry Cone {
                bottomRadius 0.03
                height 0.06
              }
            }
          ]
        }
      ]
      name "global"
    }
    DEF BODY Shape {
      appearance PBRAppearance {
        baseColor 0.917647 0.145098 0.145098
        roughness 1
        metalness 0
      }
      geometry Box {
        size 0.1 0.05 0.2
      }
    }
    DEF WHEEL1 HingeJoint {
      jointParameters HingeJointParameters {
        position -4.2864396460221646e-13
        anchor 0.06 0 0.05
      }
      device [
        RotationalMotor {
          name "wheel1"
        }
      ]
      endPoint Solid {
        translation 0.06 0 0.05
        rotation -1.2064077412980642e-09 1.2064121726893167e-09 1 1.570799999999999
        children [
          DEF WHEEL Shape {
            appearance PBRAppearance {
              baseColor 0.305882 0.898039 0.25098
              roughness 1
              metalness 0
            }
            geometry Cylinder {
              height 0.02
              radius 0.04
              subdivision 24
            }
          }
        ]
        boundingObject USE WHEEL
        physics Physics {
        }
      }
    }
    DEF WHEEL2 HingeJoint {
      jointParameters HingeJointParameters {
        position 1.2515750101107478e-11
        anchor -0.06 0 0.05
      }
      device [
        RotationalMotor {
          name "wheel2"
        }
      ]
      endPoint Solid {
        translation -0.06 0 0.05
        rotation -1.0227585634586722e-09 1.0227623202675554e-09 1 1.570799999999999
        children [
          USE WHEEL
        ]
        name "solid(1)"
        boundingObject USE WHEEL
        physics Physics {
        }
      }
    }
    DEF WHEEL3 HingeJoint {
      jointParameters HingeJointParameters {
        position -4.2971340179206553e-13
        anchor 0.06 0 -0.05
      }
      device [
        RotationalMotor {
          name "wheel3"
        }
      ]
      endPoint Solid {
        translation 0.06 0 -0.05
        rotation -5.728885553449566e-10 5.728906596859859e-10 1 1.5707999999999975
        children [
          USE WHEEL
        ]
        name "solid(2)"
        boundingObject USE WHEEL
        physics Physics {
        }
      }
    }
    DEF WHEEL4 HingeJoint {
      jointParameters HingeJointParameters {
        position 2.5439746913511256e-11
        anchor -0.06 0 -0.05
      }
      device [
        RotationalMotor {
          name "wheel4"
        }
      ]
      endPoint Solid {
        translation -0.06 0 -0.05
        rotation 7.79083417296738e-10 -7.790862790352263e-10 1 1.5707999999999995
        children [
          USE WHEEL
        ]
        name "solid(3)"
        boundingObject USE WHEEL
        physics Physics {
        }
      }
    }
    DEF DS_RIGHT DistanceSensor {
      translation -0.03 0 0.1
      rotation 0 1 0 -1.87079
      children [
        Shape {
          appearance PBRAppearance {
            baseColor 0.184314 0.596078 0.847059
            roughness 1
            metalness 0
          }
          geometry Box {
            size 0.01 0.01 0.01
          }
        }
      ]
      name "ds_right"
    }
    DEF DS_LEFT DistanceSensor {
      translation 0.03 0 0.1
      rotation 0 1 0 -1.27079
      children [
        Shape {
          appearance PBRAppearance {
            baseColor 0.184314 0.596078 0.847059
            roughness 1
            metalness 0
          }
          geometry Box {
            size 0.01 0.01 0.01
          }
        }
      ]
      name "ds_left"
    }
  ]
  name "robot(1)"
  model "ServerBot"
  description "Central system for the robots"
  boundingObject USE BODY
  physics Physics {
    density -1
    mass 1
  }
  controller "receiver"
  supervisor TRUE
}
DEF Exit Robot {
  translation 0.629002 1e-06 -0.128623
  children [
    DEF exitEmitter Emitter {
      name "exitEmitter"
      type "infra-red"
      range 0.1
      channel 2
    }
    Solid {
      children [
        Shape {
          appearance PBRAppearance {
          }
          geometry Plane {
            size 0.25 0.25
          }
        }
      ]
    }
  ]
  name "robot(2)"
  controller "exitEmitter"
  supervisor TRUE
}
