#VRML_SIM R2020a utf8
WorldInfo {
}
Viewpoint {
  orientation 1 -2.1766060587688444e-14 -1.4829829703369683e-14 4.812388980384704
  position 1.5969887791256812 5.607064673240465 1.5494031463998992
}
TexturedBackground {
}
TexturedBackgroundLight {
}
RectangleArena {
  translation 1 0 1
  floorSize 2 2
  floorTileSize 0.266667 0.266667
}
Solid {
  children [
    Wall {
      translation 1.26669 1.97065e-15 0.533094
      size 0.133333 0.1 0.266667
    }
    Wall {
      translation 0.199952 1.97065e-15 0.399287
      name "wall(9)"
      size 0.133333 0.1 0.266667
    }
    Wall {
      translation 0.133323 3.74701e-15 0.199634
      rotation 0 1 0 1.5708
      name "wall(6)"
      size 0.133333 0.1 0.266667
    }
    Wall {
      translation 0.466928 3.63599e-15 1.46677
      rotation 0 -1 0 -5.307179586466759e-06
      name "wall(7)"
      size 0.133333 0.1 0.266667
    }
    Wall {
      translation 0.200703 3.63599e-15 0.803503
      rotation 0 -1 0 -5.307179586466759e-06
      name "wall(21)"
      size 0.133333 0.1 0.266667
    }
    Wall {
      translation 0.199767 3.63599e-15 1.73239
      rotation 0 -1 0 -5.307179586466759e-06
      name "wall(23)"
      size 0.133333 0.1 0.266667
    }
    Wall {
      translation 0.733257 3.63599e-15 1.3333
      rotation 0 -1 0 -5.307179586466759e-06
      name "wall(25)"
      size 0.133333 0.1 0.266667
    }
    Wall {
      translation 0.733471 4.1911e-15 1.73264
      rotation 0 -1 0 -5.307179586466759e-06
      name "wall(26)"
      size 0.133333 0.1 0.266667
    }
    Wall {
      translation 0.466224 3.85803e-15 0.800599
      rotation 0 -1 0 -5.307179586466759e-06
      name "wall(18)"
      size 0.133333 0.1 0.266667
    }
    Wall {
      translation 1.86686 -2.41751e-14 1.7999
      rotation 0 1 0 1.5708
      name "wall(15)"
      size 0.133333 0.1 0.266667
    }
    Wall {
      translation 0.133637 4.46865e-15 0.733015
      rotation 0 1 0 1.5708
      name "wall(17)"
      size 0.133333 0.1 0.266667
    }
    Wall {
      translation 0.666594 4.56926e-15 1.53321
      rotation 0 1 0 1.5708
      name "wall(22)"
      size 0.133333 0.1 0.266667
    }
    Wall {
      translation 0.533563 4.56926e-15 1.79969
      rotation 0 1 0 1.5708
      name "wall(27)"
      size 0.133333 0.1 0.266667
    }
    Wall {
      translation 0.132649 4.57967e-15 1.53355
      rotation 0 1 0 1.5708
      name "wall(24)"
      size 0.133333 0.1 0.266667
    }
    Wall {
      translation 0.26637 4.41314e-15 1.26691
      rotation 0 1 0 1.5708
      name "wall(20)"
      size 0.133333 0.1 0.533333
    }
    Wall {
      translation 1.26673 3.58048e-15 1.13299
      rotation 0 -1 0 -5.307179586466759e-06
      name "wall(16)"
      size 0.133333 0.1 0.266667
    }
    Wall {
      translation 1.86711 3.58048e-15 0.999286
      rotation 0 1 0 1.5708
      name "wall(36)"
      size 0.133333 0.1 0.266667
    }
    Wall {
      translation 1.86703 3.74701e-15 0.732688
      rotation 0 1 0 1.5708
      name "wall(14)"
      size 0.133333 0.1 0.266667
    }
    Wall {
      translation 1.86648 3.74701e-15 0.466375
      rotation 0 1 0 1.5708
      name "wall(13)"
      size 0.133333 0.1 0.266667
    }
    Wall {
      translation 0.399656 3.74701e-15 0.466528
      rotation 0 1 0 1.5708
      name "wall(12)"
      size 0.133333 0.1 0.266667
    }
    Wall {
      translation 0.999697 2.19269e-15 0.466264
      rotation 0 1 0 1.5708
      name "wall(8)"
      size 0.133333 0.1 0.666665
    }
    Wall {
      translation 0.467368 2.19269e-15 1.00047
      rotation 0 1 0 1.5708
      name "wall(19)"
      size 0.133333 0.1 0.666665
    }
    Wall {
      translation 0.999732 2.08444e-14 1.73225
      rotation 0 -1 0 -5.307179586466759e-06
      name "wall(34)"
      size 0.133333 0.1 0.533333
    }
    Wall {
      translation 1.20012 2.06224e-14 1.00007
      rotation 0 1 0 1.5708
      name "wall(35)"
      size 0.133333 0.1 0.533333
    }
    Wall {
      translation 1.46678 -6.13397e-15 1.26659
      rotation 0 1 0 1.5708
      name "wall(29)"
      size 0.1333 0.1 1.06664
    }
    Wall {
      translation 1.20027 4.68028e-15 1.53313
      rotation 0 1 0 1.5708
      name "wall(28)"
      size 0.133333 0.1 0.266667
    }
    Wall {
      translation 1.73257 4.56926e-15 1.53329
      rotation 0 1 0 1.5708
      name "wall(33)"
      size 0.133333 0.1 0.266667
    }
    Wall {
      translation 1.46646 4.56926e-15 1.79987
      rotation 0 1 0 1.5708
      name "wall(30)"
      size 0.133333 0.1 0.266667
    }
    Wall {
      translation 1.26673 4.84681e-15 1.86664
      rotation 0 1 0 -3.1415853071795863
      name "wall(31)"
      size 0.133333 0.1 0.266667
    }
    Wall {
      translation 1.53356 4.7913e-15 1.59972
      rotation 0 1 0 -3.1415853071795863
      name "wall(32)"
      size 0.133333 0.1 0.266667
    }
    Wall {
      translation 0.866661 2.25653e-14 0.732339
      rotation 0 1 0 1.5708
      name "wall(10)"
      size 0.133333 0.1 0.933333
    }
    Wall {
      translation 1.53344 1.76803e-14 0.60042
      rotation 0 -1 0 -5.307179586466759e-06
      name "wall(11)"
      size 0.133333 0.1 0.933333
    }
    Wall {
      translation 0.466716 1.97065e-15 0.133017
      name "wall(1)"
      size 0.133333 0.1 0.266667
    }
    Wall {
      translation 0.733087 1.97065e-15 0.132689
      name "wall(2)"
      size 0.133333 0.1 0.266667
    }
    Wall {
      translation 1.00048 -9.35362e-15 0.132886
      name "wall(3)"
      size 0.133333 0.1 0.266667
    }
    Wall {
      translation 1.79832 -1.63757e-15 0.26553
      name "wall(5)"
      size 0.133333 0.1 0.266667
    }
    Wall {
      translation 1.26702 1.91514e-15 0.132869
      name "wall(4)"
      size 0.133333 0.1 0.266667
    }
  ]
}
DEF botJr Robot {
  translation 0.1774088525086539 0.010797435182212763 0.058193892821533276
  rotation 4.8860033095066345e-06 0.9999999999739027 -5.321812258437297e-06 1.6545397612196366
  children [
    DEF compass Compass {
    }
    DEF emitter Emitter {
    }
    DEF DS_FRONT DistanceSensor {
      translation 3.30588e-07 0.004 0.015
      rotation 0 -1 0 1.5708
      children [
        Shape {
          appearance PBRAppearance {
            baseColor 0.184314 0.596078 0.847059
            roughness 1
            metalness 0
          }
          geometry Box {
            size 0.002 0.002 0.002
          }
        }
      ]
      name "ds_front"
    }
    DEF DS_BACK DistanceSensor {
      translation -3.33883e-06 0.004 -0.015
      rotation 0 -1 0 -1.5708
      children [
        Shape {
          appearance PBRAppearance {
            baseColor 0.184314 0.596078 0.847059
            roughness 1
            metalness 0
          }
          geometry Box {
            size 0.002 0.002 0.002
          }
        }
      ]
      name "ds_back"
    }
    DEF DS_LEFT DistanceSensor {
      translation 0.012 0.004 0
      rotation 0 -1 0 0
      children [
        Shape {
          appearance PBRAppearance {
            baseColor 0.184314 0.596078 0.847059
            roughness 1
            metalness 0
          }
          geometry Sphere {
            radius 0.001
          }
        }
      ]
      name "ds_left"
    }
    DEF DS_RIGHT DistanceSensor {
      translation -0.012 0.004 0
      rotation 0 -1 0 -3.1415
      children [
        Shape {
          appearance PBRAppearance {
            baseColor 0.184314 0.596078 0.847059
            roughness 1
            metalness 0
          }
          geometry Sphere {
            radius 0.001
          }
        }
      ]
      name "ds_right"
    }
    GPS {
      translation 0 -0.003 0.006
      children [
        Solid {
          translation 0 0.02 0
          rotation 0 1 0 0.523599
          children [
            Shape {
              appearance PBRAppearance {
                baseColor 1 1 0.0980392
                roughness 1
                metalness 0
              }
              geometry Cone {
                bottomRadius 0.007
                height 0.02
                subdivision 36
              }
            }
          ]
        }
      ]
      name "global"
    }
    DEF WHEEL1 HingeJoint {
      jointParameters HingeJointParameters {
        position 1249.613618776915
        anchor 0.0141 -0.0048 0.007
      }
      device [
        RotationalMotor {
          name "wheel1"
        }
      ]
      endPoint Solid {
        translation 0.014100000000000001 -0.004799991243424082 0.007000006063598761
        rotation 0.34866890267418627 -0.3486701834088682 -0.8699764936534808 4.573544485364312
        children [
          DEF WHEEL Shape {
            appearance PBRAppearance {
              baseColor 1 0 0
              roughness 1
              metalness 0
            }
            geometry Cylinder {
              height 0.003
              radius 0.006
            }
          }
        ]
        boundingObject USE WHEEL
        physics Physics {
        }
        linearVelocity 0.05978967423855117 3.6350648036540893e-09 -0.005018625133145638
        angularVelocity -0.8364582965544756 -9.862404408130876e-07 -9.964957993853332
      }
    }
    DEF WHEEL2 HingeJoint {
      jointParameters HingeJointParameters {
        position 1234.7336194503296
        anchor -0.0141 -0.0048 0.007
      }
      device [
        RotationalMotor {
          name "wheel2"
        }
      ]
      endPoint Solid {
        translation -0.014100000000000001 -0.004799991243424095 0.00700000606359878
        rotation 0.7069152115813142 -0.706917808230528 -0.02319689723847956 3.187977958991352
        children [
          DEF WHEEL Shape {
            appearance PBRAppearance {
              baseColor 1 0 0
              roughness 1
              metalness 0
            }
            geometry Cylinder {
              height 0.003
              radius 0.006
            }
          }
        ]
        name "solid(3)"
        boundingObject USE WHEEL
        physics Physics {
        }
        linearVelocity 0.05978967944621325 -1.699685601155085e-09 -0.005018812167498122
        angularVelocity -0.8364582982380728 -9.876295922102061e-07 -9.964957993962836
      }
    }
    DEF WHEEL3 HingeJoint {
      jointParameters HingeJointParameters {
        position 1234.7336204998294
        anchor 0.0141 -0.0048 -0.0075
      }
      device [
        RotationalMotor {
          name "wheel3"
        }
      ]
      endPoint Solid {
        translation 0.014100000000000001 -0.004799991243424448 -0.007499993936400708
        rotation 0.7069152054917062 -0.7069178021408962 -0.023197268393139046 3.187978700898721
        children [
          DEF WHEEL Shape {
            appearance PBRAppearance {
              baseColor 1 0 0
              roughness 1
              metalness 0
            }
            geometry Cylinder {
              height 0.003
              radius 0.006
            }
          }
        ]
        name "solid(1)"
        boundingObject USE WHEEL
        physics Physics {
        }
        linearVelocity 0.05978981339073762 4.4310122289105914e-08 -0.005018692563566285
        angularVelocity -0.8364582971858207 -9.867692201295105e-07 -9.964957995538093
      }
    }
    DEF WHEEL4 HingeJoint {
      jointParameters HingeJointParameters {
        position 1249.6136202737787
        anchor -0.0141 -0.0048 -0.0075
      }
      device [
        RotationalMotor {
          name "wheel4"
        }
      ]
      endPoint Solid {
        translation -0.014100000000000001 -0.00479999124342447 -0.007499993936400679
        rotation 0.34866833071433995 -0.3486696114469206 -0.8699769521144392 4.573545007273715
        children [
          DEF WHEEL Shape {
            appearance PBRAppearance {
              baseColor 1 0 0
              roughness 1
              metalness 0
            }
            geometry Cylinder {
              height 0.003
              radius 0.006
            }
          }
        ]
        name "solid(2)"
        boundingObject USE WHEEL
        physics Physics {
        }
        linearVelocity 0.05978982479849521 3.872579566537577e-08 -0.005018869279561637
        angularVelocity -0.8364582986539488 -9.87754465064877e-07 -9.964957995729382
      }
    }
    DEF BODY Shape {
      appearance PBRAppearance {
        baseColor 0.054902 1 0.352941
        roughness 1
        metalness 0
      }
      geometry Box {
        size 0.025 0.015 0.03
      }
    }
  ]
  boundingObject USE BODY
  physics Physics {
  }
  controller "slaveController_test"
  supervisor TRUE
  linearVelocity 0.059789350314625414 -2.520820221736196e-07 -0.005018718549414851
  angularVelocity -2.0251556184026963e-07 -1.6298992378299071e-06 -2.507912363513519e-06
}
DEF botJr2 Robot {
  translation 1.9358000000863598 0.01079746881578836 0.18913230071291218
  rotation -0.9999941785238499 0.003279671187880661 -0.0009416343825017016 -1.0710551799245132e-05
  children [
    DEF compass Compass {
    }
    DEF emitter Emitter {
    }
    DEF DS_FRONT DistanceSensor {
      translation 3.30588e-07 0.004 0.015
      rotation 0 -1 0 1.5708
      children [
        Shape {
          appearance PBRAppearance {
            baseColor 0.184314 0.596078 0.847059
            roughness 1
            metalness 0
          }
          geometry Box {
            size 0.002 0.002 0.002
          }
        }
      ]
      name "ds_front"
    }
    DEF DS_BACK DistanceSensor {
      translation -3.33883e-06 0.004 -0.015
      rotation 0 -1 0 -1.5708
      children [
        Shape {
          appearance PBRAppearance {
            baseColor 0.184314 0.596078 0.847059
            roughness 1
            metalness 0
          }
          geometry Box {
            size 0.002 0.002 0.002
          }
        }
      ]
      name "ds_back"
    }
    DEF DS_LEFT DistanceSensor {
      translation 0.012 0.004 0
      rotation 0 -1 0 0
      children [
        Shape {
          appearance PBRAppearance {
            baseColor 0.184314 0.596078 0.847059
            roughness 1
            metalness 0
          }
          geometry Sphere {
            radius 0.001
          }
        }
      ]
      name "ds_left"
    }
    DEF DS_RIGHT DistanceSensor {
      translation -0.012 0.004 0
      rotation 0 -1 0 -3.1415
      children [
        Shape {
          appearance PBRAppearance {
            baseColor 0.184314 0.596078 0.847059
            roughness 1
            metalness 0
          }
          geometry Sphere {
            radius 0.001
          }
        }
      ]
      name "ds_right"
    }
    GPS {
      translation 0 -0.003 0.006
      children [
        Solid {
          translation 0 0.02 0
          rotation 0 1 0 0.523599
          children [
            Shape {
              appearance PBRAppearance {
                baseColor 1 1 0.0980392
                roughness 1
                metalness 0
              }
              geometry Cone {
                bottomRadius 0.007
                height 0.02
                subdivision 36
              }
            }
          ]
        }
      ]
      name "global"
    }
    DEF WHEEL1 HingeJoint {
      jointParameters HingeJointParameters {
        position 1249.6447065475634
        anchor 0.0141 -0.0048 0.007
      }
      device [
        RotationalMotor {
          name "wheel1"
        }
      ]
      endPoint Solid {
        translation 0.014100000000000001 -0.004799991436128541 0.007000006332847494
        rotation 0.3366694927226209 -0.33667072938092996 -0.879378458144163 4.584197930603932
        children [
          DEF WHEEL Shape {
            appearance PBRAppearance {
              baseColor 1 0 0
              roughness 1
              metalness 0
            }
            geometry Cylinder {
              height 0.003
              radius 0.006
            }
          }
        ]
        boundingObject USE WHEEL
        physics Physics {
        }
        linearVelocity -1.8659063745315547e-09 -1.82451668536398e-09 0.06000000130141403
        angularVelocity 9.999999998232662 -3.0692397581267114e-08 1.985555163253101e-07
      }
    }
    DEF WHEEL2 HingeJoint {
      jointParameters HingeJointParameters {
        position 1234.764707220075
        anchor -0.0141 -0.0048 0.007
      }
      device [
        RotationalMotor {
          name "wheel2"
        }
      ]
      endPoint Solid {
        translation -0.014100000000000001 -0.004799991436128549 0.007000006332847504
        rotation 0.7066920092189696 -0.7066946050483138 -0.03419267906530905 3.2099511288302303
        children [
          DEF WHEEL Shape {
            appearance PBRAppearance {
              baseColor 1 0 0
              roughness 1
              metalness 0
            }
            geometry Cylinder {
              height 0.003
              radius 0.006
            }
          }
        ]
        name "solid(3)"
        boundingObject USE WHEEL
        physics Physics {
        }
        linearVelocity -1.86575093314907e-09 1.884716045103738e-09 0.05999999867674237
        angularVelocity 9.999999998201222 -3.0825969009979856e-08 1.9848801530167388e-07
      }
    }
    DEF WHEEL3 HingeJoint {
      jointParameters HingeJointParameters {
        position 1234.7647082659394
        anchor 0.0141 -0.0048 -0.0075
      }
      device [
        RotationalMotor {
          name "wheel3"
        }
      ]
      endPoint Solid {
        translation 0.014100000000000001 -0.004799991436128895 -0.007499993667152026
        rotation 0.7066920002682439 -0.7066945960975537 -0.034193049050705374 3.209951867934184
        children [
          DEF WHEEL Shape {
            appearance PBRAppearance {
              baseColor 1 0 0
              roughness 1
              metalness 0
            }
            geometry Cylinder {
              height 0.003
              radius 0.006
            }
          }
        ]
        name "solid(1)"
        boundingObject USE WHEEL
        physics Physics {
        }
        linearVelocity -5.163209071974962e-10 -1.8498785003880203e-09 0.0600000013012606
        angularVelocity 9.999999998232695 -3.0835857748809924e-08 1.984823791133849e-07
      }
    }
    DEF WHEEL4 HingeJoint {
      jointParameters HingeJointParameters {
        position 1249.6447080386738
        anchor -0.0141 -0.0048 -0.0075
      }
      device [
        RotationalMotor {
          name "wheel4"
        }
      ]
      endPoint Solid {
        translation -0.014100000000000001 -0.00479999143612891 -0.007499993667152008
        rotation 0.3366689114120114 -0.33667014806818524 -0.8793789032541078 4.584198432614911
        children [
          DEF WHEEL Shape {
            appearance PBRAppearance {
              baseColor 1 0 0
              roughness 1
              metalness 0
            }
            geometry Cylinder {
              height 0.003
              radius 0.006
            }
          }
        ]
        name "solid(2)"
        boundingObject USE WHEEL
        physics Physics {
        }
        linearVelocity -5.164779008262682e-10 1.8593557025646275e-09 0.05999999867698861
        angularVelocity 9.999999998201156 -3.070233085926786e-08 1.985502578159685e-07
      }
    }
    DEF BODY Shape {
      appearance PBRAppearance {
        baseColor 0.054902 1 0.352941
        roughness 1
        metalness 0
      }
      geometry Box {
        size 0.025 0.015 0.03
      }
    }
  ]
  name "robot(1)"
  boundingObject USE BODY
  physics Physics {
  }
  controller "slaveController_test2"
  supervisor TRUE
  linearVelocity -5.817068320542627e-10 2.381403581984352e-08 0.05999988784896178
  angularVelocity -1.7830902478900196e-09 -1.38302767415648e-07 -1.341638121288931e-07
}
DEF botJr3 Robot {
  translation 0.05652302544625241 0.010797468808597898 1.8257497869876724
  rotation 5.023028775693389e-09 0.9999999999856607 -5.355240782985266e-06 -3.141585339366282
  children [
    DEF compass Compass {
    }
    DEF emitter Emitter {
    }
    DEF DS_FRONT DistanceSensor {
      translation 3.30588e-07 0.004 0.015
      rotation 0 -1 0 1.5708
      children [
        Shape {
          appearance PBRAppearance {
            baseColor 0.184314 0.596078 0.847059
            roughness 1
            metalness 0
          }
          geometry Box {
            size 0.002 0.002 0.002
          }
        }
      ]
      name "ds_front"
    }
    DEF DS_BACK DistanceSensor {
      translation -3.33883e-06 0.004 -0.015
      rotation 0 -1 0 -1.5708
      children [
        Shape {
          appearance PBRAppearance {
            baseColor 0.184314 0.596078 0.847059
            roughness 1
            metalness 0
          }
          geometry Box {
            size 0.002 0.002 0.002
          }
        }
      ]
      name "ds_back"
    }
    DEF DS_LEFT DistanceSensor {
      translation 0.012 0.004 0
      rotation 0 -1 0 0
      children [
        Shape {
          appearance PBRAppearance {
            baseColor 0.184314 0.596078 0.847059
            roughness 1
            metalness 0
          }
          geometry Sphere {
            radius 0.001
          }
        }
      ]
      name "ds_left"
    }
    DEF DS_RIGHT DistanceSensor {
      translation -0.012 0.004 0
      rotation 0 -1 0 -3.1415
      children [
        Shape {
          appearance PBRAppearance {
            baseColor 0.184314 0.596078 0.847059
            roughness 1
            metalness 0
          }
          geometry Sphere {
            radius 0.001
          }
        }
      ]
      name "ds_right"
    }
    GPS {
      translation 0 -0.003 0.006
      children [
        Solid {
          translation 0 0.02 0
          rotation 0 1 0 0.523599
          children [
            Shape {
              appearance PBRAppearance {
                baseColor 1 1 0.0980392
                roughness 1
                metalness 0
              }
              geometry Cone {
                bottomRadius 0.007
                height 0.02
                subdivision 36
              }
            }
          ]
        }
      ]
      name "global"
    }
    DEF WHEEL1 HingeJoint {
      jointParameters HingeJointParameters {
        position 1249.6447065475634
        anchor 0.0141 -0.0048 0.007
      }
      device [
        RotationalMotor {
          name "wheel1"
        }
      ]
      endPoint Solid {
        translation 0.014100000000000001 -0.004799991436128541 0.007000006332847494
        rotation 0.3366694927226209 -0.33667072938092996 -0.879378458144163 4.584197930603932
        children [
          DEF WHEEL Shape {
            appearance PBRAppearance {
              baseColor 1 0 0
              roughness 1
              metalness 0
            }
            geometry Cylinder {
              height 0.003
              radius 0.006
            }
          }
        ]
        boundingObject USE WHEEL
        physics Physics {
        }
        linearVelocity -4.390951371136139e-07 -1.7687791006639368e-09 -0.06000000130017752
        angularVelocity -9.999999998025967 -3.06924543968278e-08 7.329494995660137e-05
      }
    }
    DEF WHEEL2 HingeJoint {
      jointParameters HingeJointParameters {
        position 1234.7647072200753
        anchor -0.0141 -0.0048 0.007
      }
      device [
        RotationalMotor {
          name "wheel2"
        }
      ]
      endPoint Solid {
        translation -0.014100000000000001 -0.004799991436128549 0.007000006332847504
        rotation 0.7066920092189678 -0.7066946050483119 -0.0341926790653895 3.209951128830391
        children [
          DEF WHEEL Shape {
            appearance PBRAppearance {
              baseColor 1 0 0
              roughness 1
              metalness 0
            }
            geometry Cylinder {
              height 0.003
              radius 0.006
            }
          }
        ]
        name "solid(3)"
        boundingObject USE WHEEL
        physics Physics {
        }
        linearVelocity -4.390952751782941e-07 1.940451175686947e-09 -0.059999998675505296
        angularVelocity -9.999999997994408 -3.082609621400304e-08 7.329501810751483e-05
      }
    }
    DEF WHEEL3 HingeJoint {
      jointParameters HingeJointParameters {
        position 1234.7647082659391
        anchor 0.0141 -0.0048 -0.0075
      }
      device [
        RotationalMotor {
          name "wheel3"
        }
      ]
      endPoint Solid {
        translation 0.014100000000000001 -0.004799991436128895 -0.007499993667152026
        rotation 0.7066920002682456 -0.7066945960975556 -0.03419304905062494 3.209951867934023
        children [
          DEF WHEEL Shape {
            appearance PBRAppearance {
              baseColor 1 0 0
              roughness 1
              metalness 0
            }
            geometry Cylinder {
              height 0.003
              radius 0.006
            }
          }
        ]
        name "solid(1)"
        boundingObject USE WHEEL
        physics Physics {
        }
        linearVelocity -4.4044472300375037e-07 -1.793244666793205e-09 -0.06000000130001693
        angularVelocity -9.999999998025915 -3.083617472612476e-08 7.329502341349628e-05
      }
    }
    DEF WHEEL4 HingeJoint {
      jointParameters HingeJointParameters {
        position 1249.6447080386738
        anchor -0.0141 -0.0048 -0.0075
      }
      device [
        RotationalMotor {
          name "wheel4"
        }
      ]
      endPoint Solid {
        translation -0.014100000000000001 -0.00479999143612891 -0.007499993667152008
        rotation 0.3366689114120114 -0.33667014806818524 -0.8793789032541078 4.584198432614911
        children [
          DEF WHEEL Shape {
            appearance PBRAppearance {
              baseColor 1 0 0
              roughness 1
              metalness 0
            }
            geometry Cylinder {
              height 0.003
              radius 0.006
            }
          }
        ]
        name "solid(2)"
        boundingObject USE WHEEL
        physics Physics {
        }
        linearVelocity -4.4044454721760025e-07 1.9159862640200548e-09 -0.05999999867574469
        angularVelocity -9.999999997994472 -3.070245872444687e-08 7.329495551271136e-05
      }
    }
    DEF BODY Shape {
      appearance PBRAppearance {
        baseColor 0.054902 1 0.352941
        roughness 1
        metalness 0
      }
      geometry Box {
        size 0.025 0.015 0.03
      }
    }
  ]
  name "robot(2)"
  boundingObject USE BODY
  physics Physics {
  }
  controller "slaveController_test3"
  supervisor TRUE
  linearVelocity -4.4037850089299617e-07 2.3870183972642424e-08 -0.0599998878480099
  angularVelocity 1.7221448202232765e-09 -1.383027932182124e-07 1.3416364642730474e-07
}
DEF botJr4 Robot {
  translation 1.8119498933317195 0.010797468815225648 1.9410300121138446
  rotation -5.350207347680799e-06 0.9999999999713214 -5.360283398890025e-06 -1.5707953476134546
  children [
    DEF compass Compass {
    }
    DEF emitter Emitter {
    }
    DEF DS_FRONT DistanceSensor {
      translation 3.30588e-07 0.004 0.015
      rotation 0 -1 0 1.5708
      children [
        Shape {
          appearance PBRAppearance {
            baseColor 0.184314 0.596078 0.847059
            roughness 1
            metalness 0
          }
          geometry Box {
            size 0.002 0.002 0.002
          }
        }
      ]
      name "ds_front"
    }
    DEF DS_BACK DistanceSensor {
      translation -3.33883e-06 0.004 -0.015
      rotation 0 -1 0 -1.5708
      children [
        Shape {
          appearance PBRAppearance {
            baseColor 0.184314 0.596078 0.847059
            roughness 1
            metalness 0
          }
          geometry Box {
            size 0.002 0.002 0.002
          }
        }
      ]
      name "ds_back"
    }
    DEF DS_LEFT DistanceSensor {
      translation 0.012 0.004 0
      rotation 0 -1 0 0
      children [
        Shape {
          appearance PBRAppearance {
            baseColor 0.184314 0.596078 0.847059
            roughness 1
            metalness 0
          }
          geometry Sphere {
            radius 0.001
          }
        }
      ]
      name "ds_left"
    }
    DEF DS_RIGHT DistanceSensor {
      translation -0.012 0.004 0
      rotation 0 -1 0 -3.1415
      children [
        Shape {
          appearance PBRAppearance {
            baseColor 0.184314 0.596078 0.847059
            roughness 1
            metalness 0
          }
          geometry Sphere {
            radius 0.001
          }
        }
      ]
      name "ds_right"
    }
    GPS {
      translation 0 -0.003 0.006
      children [
        Solid {
          translation 0 0.02 0
          rotation 0 1 0 0.523599
          children [
            Shape {
              appearance PBRAppearance {
                baseColor 1 1 0.0980392
                roughness 1
                metalness 0
              }
              geometry Cone {
                bottomRadius 0.007
                height 0.02
                subdivision 36
              }
            }
          ]
        }
      ]
      name "global"
    }
    DEF WHEEL1 HingeJoint {
      jointParameters HingeJointParameters {
        position 1249.644706547564
        anchor 0.0141 -0.0048 0.007
      }
      device [
        RotationalMotor {
          name "wheel1"
        }
      ]
      endPoint Solid {
        translation 0.014100000000000001 -0.004799991436128541 0.007000006332847494
        rotation 0.3366694927223551 -0.3366707293806641 -0.8793784581443668 4.584197930604162
        children [
          DEF WHEEL Shape {
            appearance PBRAppearance {
              baseColor 1 0 0
              roughness 1
              metalness 0
            }
            geometry Cylinder {
              height 0.003
              radius 0.006
            }
          }
        ]
        boundingObject USE WHEEL
        physics Physics {
        }
        linearVelocity -0.06000000130156549 -1.8199047174613234e-09 5.8994098146328704e-08
        angularVelocity 9.944776361227727e-06 -3.073899350538282e-08 9.999999998258623
      }
    }
    DEF WHEEL2 HingeJoint {
      jointParameters HingeJointParameters {
        position 1234.7647072200732
        anchor -0.0141 -0.0048 0.007
      }
      device [
        RotationalMotor {
          name "wheel2"
        }
      ]
      endPoint Solid {
        translation -0.014100000000000001 -0.004799991436128549 0.007000006332847504
        rotation 0.7066920092189852 -0.7066946050483297 -0.03419267906466558 3.209951128828945
        children [
          DEF WHEEL Shape {
            appearance PBRAppearance {
              baseColor 1 0 0
              roughness 1
              metalness 0
            }
            geometry Cylinder {
              height 0.003
              radius 0.006
            }
          }
        ]
        name "solid(3)"
        boundingObject USE WHEEL
        physics Physics {
        }
        linearVelocity -0.05999999867688996 1.88846121368577e-09 5.8994227634399654e-08
        angularVelocity 9.944844178021045e-06 -3.0872629907465716e-08 9.9999999982271
      }
    }
    DEF WHEEL3 HingeJoint {
      jointParameters HingeJointParameters {
        position 1234.76470826594
        anchor 0.0141 -0.0048 -0.0075
      }
      device [
        RotationalMotor {
          name "wheel3"
        }
      ]
      endPoint Solid {
        translation 0.014100000000000001 -0.004799991436128895 -0.007499993667152026
        rotation 0.7066920002682379 -0.7066945960975479 -0.034193049050946674 3.2099518679346657
        children [
          DEF WHEEL Shape {
            appearance PBRAppearance {
              baseColor 1 0 0
              roughness 1
              metalness 0
            }
            geometry Cylinder {
              height 0.003
              radius 0.006
            }
          }
        ]
        name "solid(1)"
        boundingObject USE WHEEL
        physics Physics {
        }
        linearVelocity -0.06000000130142581 -1.8448175899981091e-09 6.034368370538318e-08
        angularVelocity 9.944849481361393e-06 -3.08825890952281e-08 9.99999999825866
      }
    }
    DEF WHEEL4 HingeJoint {
      jointParameters HingeJointParameters {
        position 1249.644708038672
        anchor -0.0141 -0.0048 -0.0075
      }
      device [
        RotationalMotor {
          name "wheel4"
        }
      ]
      endPoint Solid {
        translation -0.014100000000000001 -0.00479999143612891 -0.007499993667152008
        rotation 0.3366689114127206 -0.33667014806889434 -0.8793789032535648 4.584198432614299
        children [
          DEF WHEEL Shape {
            appearance PBRAppearance {
              baseColor 1 0 0
              roughness 1
              metalness 0
            }
            geometry Cylinder {
              height 0.003
              radius 0.006
            }
          }
        ]
        name "solid(2)"
        boundingObject USE WHEEL
        physics Physics {
        }
        linearVelocity -0.0599999986771477 1.863543596506004e-09 6.034350006051422e-08
        angularVelocity 9.944781482629703e-06 -3.0748963429163574e-08 9.999999998227128
      }
    }
    DEF BODY Shape {
      appearance PBRAppearance {
        baseColor 0.054902 1 0.352941
        roughness 1
        metalness 0
      }
      geometry Box {
        size 0.025 0.015 0.03
      }
    }
  ]
  name "robot(3)"
  boundingObject USE BODY
  physics Physics {
  }
  controller "slaveController_test4"
  supervisor TRUE
  linearVelocity -0.05999988784926274 2.3818419039557583e-08 6.027801954529395e-08
  angularVelocity 1.3413296687336054e-07 -1.3830140515881728e-07 -1.7523070479698124e-09
}
